In Next.js, a subtle issue can arise when using the `getStaticPaths` function with dynamic routes. If the paths are not generated correctly or the fallback mechanism isn't implemented properly, it can lead to unexpected behavior.  For example, if a path is requested that doesn't exist in the generated `paths` array, and the `fallback` is set to `false`, Next.js will return a 404 error. However, if there's an issue within the `getStaticPaths` function itself, such as a network request error, or an unexpected value being returned, it could lead to unexpected 404 errors even when paths *should* exist.  This error is not always easily debugged, as the underlying issue may be hidden within the asynchronous operation of fetching data within `getStaticPaths`. Consider this example: 
```javascript
export async function getStaticPaths() {
  const res = await fetch('https://api.example.com/posts');
  if (!res.ok) {
    //Error handling is missing here and could cause unexpected behavior
    return { paths: [], fallback: false };
  }
  const posts = await res.json();
  const paths = posts.map((post) => ({
    params: { id: post.id },
  }));
  return { paths, fallback: false };
}
```